[2024-09-04T05:09:00.484+0000] {local_task_job_runner.py:123} INFO - ::group::Pre task execution logs
[2024-09-04T05:09:00.490+0000] {taskinstance.py:2603} INFO - Dependencies all met for dep_context=non-requeueable deps ti=<TaskInstance: weather_dag.transform_load_weather_data manual__2024-09-04T05:06:47.581164+00:00 [queued]>
[2024-09-04T05:09:00.494+0000] {taskinstance.py:2603} INFO - Dependencies all met for dep_context=requeueable deps ti=<TaskInstance: weather_dag.transform_load_weather_data manual__2024-09-04T05:06:47.581164+00:00 [queued]>
[2024-09-04T05:09:00.494+0000] {taskinstance.py:2856} INFO - Starting attempt 2 of 3
[2024-09-04T05:09:00.508+0000] {taskinstance.py:2879} INFO - Executing <Task(PythonOperator): transform_load_weather_data> on 2024-09-04 05:06:47.581164+00:00
[2024-09-04T05:09:00.512+0000] {standard_task_runner.py:72} INFO - Started process 11305 to run task
[2024-09-04T05:09:00.517+0000] {standard_task_runner.py:104} INFO - Running: ['airflow', 'tasks', 'run', 'weather_dag', 'transform_load_weather_data', 'manual__2024-09-04T05:06:47.581164+00:00', '--job-id', '12', '--raw', '--subdir', 'DAGS_FOLDER/weather_dag.py', '--cfg-path', '/tmp/tmpp9vks0w5']
[2024-09-04T05:09:00.517+0000] {standard_task_runner.py:105} INFO - Job 12: Subtask transform_load_weather_data
[2024-09-04T05:09:00.547+0000] {task_command.py:467} INFO - Running <TaskInstance: weather_dag.transform_load_weather_data manual__2024-09-04T05:06:47.581164+00:00 [running]> on host ip-172-31-40-195.ap-southeast-2.compute.internal
[2024-09-04T05:09:00.745+0000] {taskinstance.py:3122} INFO - Exporting env vars: AIRFLOW_CTX_DAG_EMAIL='myemail@domain.com' AIRFLOW_CTX_DAG_OWNER='airflow' AIRFLOW_CTX_DAG_ID='weather_dag' AIRFLOW_CTX_TASK_ID='transform_load_weather_data' AIRFLOW_CTX_EXECUTION_DATE='2024-09-04T05:06:47.581164+00:00' AIRFLOW_CTX_TRY_NUMBER='2' AIRFLOW_CTX_DAG_RUN_ID='manual__2024-09-04T05:06:47.581164+00:00'
[2024-09-04T05:09:00.746+0000] {logging_mixin.py:190} INFO - Task instance is in running state
[2024-09-04T05:09:00.746+0000] {logging_mixin.py:190} INFO -  Previous state of the Task instance: queued
[2024-09-04T05:09:00.746+0000] {logging_mixin.py:190} INFO - Current task name:transform_load_weather_data state:running start_date:2024-09-04 05:09:00.490695+00:00
[2024-09-04T05:09:00.747+0000] {logging_mixin.py:190} INFO - Dag name:weather_dag and current dag run status:running
[2024-09-04T05:09:00.747+0000] {taskinstance.py:731} INFO - ::endgroup::
[2024-09-04T05:09:02.509+0000] {taskinstance.py:3301} ERROR - Task failed with exception
Traceback (most recent call last):
  File "/home/ubuntu/airflow_venv/lib/python3.12/site-packages/s3fs/core.py", line 113, in _error_wrapper
    return await func(*args, **kwargs)
           ^^^^^^^^^^^^^^^^^^^^^^^^^^^
  File "/home/ubuntu/airflow_venv/lib/python3.12/site-packages/aiobotocore/client.py", line 412, in _make_api_call
    raise error_class(parsed_response, operation_name)
botocore.exceptions.ClientError: An error occurred (InvalidAccessKeyId) when calling the PutObject operation: The AWS Access Key Id you provided does not exist in our records.

The above exception was the direct cause of the following exception:

Traceback (most recent call last):
  File "/home/ubuntu/airflow_venv/lib/python3.12/site-packages/airflow/models/taskinstance.py", line 767, in _execute_task
    result = _execute_callable(context=context, **execute_callable_kwargs)
             ^^^^^^^^^^^^^^^^^^^^^^^^^^^^^^^^^^^^^^^^^^^^^^^^^^^^^^^^^^^^^
  File "/home/ubuntu/airflow_venv/lib/python3.12/site-packages/airflow/models/taskinstance.py", line 733, in _execute_callable
    return ExecutionCallableRunner(
           ^^^^^^^^^^^^^^^^^^^^^^^^
  File "/home/ubuntu/airflow_venv/lib/python3.12/site-packages/airflow/utils/operator_helpers.py", line 252, in run
    return self.func(*args, **kwargs)
           ^^^^^^^^^^^^^^^^^^^^^^^^^^
  File "/home/ubuntu/airflow_venv/lib/python3.12/site-packages/airflow/models/baseoperator.py", line 406, in wrapper
    return func(self, *args, **kwargs)
           ^^^^^^^^^^^^^^^^^^^^^^^^^^^
  File "/home/ubuntu/airflow_venv/lib/python3.12/site-packages/airflow/operators/python.py", line 238, in execute
    return_value = self.execute_callable()
                   ^^^^^^^^^^^^^^^^^^^^^^^
  File "/home/ubuntu/airflow_venv/lib/python3.12/site-packages/airflow/operators/python.py", line 256, in execute_callable
    return runner.run(*self.op_args, **self.op_kwargs)
           ^^^^^^^^^^^^^^^^^^^^^^^^^^^^^^^^^^^^^^^^^^^
  File "/home/ubuntu/airflow_venv/lib/python3.12/site-packages/airflow/utils/operator_helpers.py", line 252, in run
    return self.func(*args, **kwargs)
           ^^^^^^^^^^^^^^^^^^^^^^^^^^
  File "/home/ubuntu/airflow/dags/weather_dag.py", line 50, in transform_load_data
    df_data.to_csv(f"s3://weatherapiairflowyoutubebucket-yml/{dt_string}.csv", index=False, storage_options=aws_credentials)
  File "/home/ubuntu/airflow_venv/lib/python3.12/site-packages/pandas/util/_decorators.py", line 333, in wrapper
    return func(*args, **kwargs)
           ^^^^^^^^^^^^^^^^^^^^^
  File "/home/ubuntu/airflow_venv/lib/python3.12/site-packages/pandas/core/generic.py", line 3967, in to_csv
    return DataFrameRenderer(formatter).to_csv(
           ^^^^^^^^^^^^^^^^^^^^^^^^^^^^^^^^^^^^
  File "/home/ubuntu/airflow_venv/lib/python3.12/site-packages/pandas/io/formats/format.py", line 1014, in to_csv
    csv_formatter.save()
  File "/home/ubuntu/airflow_venv/lib/python3.12/site-packages/pandas/io/formats/csvs.py", line 251, in save
    with get_handle(
  File "/home/ubuntu/airflow_venv/lib/python3.12/site-packages/pandas/io/common.py", line 157, in __exit__
    self.close()
  File "/home/ubuntu/airflow_venv/lib/python3.12/site-packages/pandas/io/common.py", line 144, in close
    handle.close()
  File "/home/ubuntu/airflow_venv/lib/python3.12/site-packages/fsspec/spec.py", line 2035, in close
    self.flush(force=True)
  File "/home/ubuntu/airflow_venv/lib/python3.12/site-packages/fsspec/spec.py", line 1899, in flush
    if self._upload_chunk(final=force) is not False:
       ^^^^^^^^^^^^^^^^^^^^^^^^^^^^^^^
  File "/home/ubuntu/airflow_venv/lib/python3.12/site-packages/s3fs/core.py", line 2371, in _upload_chunk
    self.commit()
  File "/home/ubuntu/airflow_venv/lib/python3.12/site-packages/s3fs/core.py", line 2389, in commit
    write_result = self._call_s3("put_object", **kw)
                   ^^^^^^^^^^^^^^^^^^^^^^^^^^^^^^^^^
  File "/home/ubuntu/airflow_venv/lib/python3.12/site-packages/s3fs/core.py", line 2234, in _call_s3
    return self.fs.call_s3(method, self.s3_additional_kwargs, *kwarglist, **kwargs)
           ^^^^^^^^^^^^^^^^^^^^^^^^^^^^^^^^^^^^^^^^^^^^^^^^^^^^^^^^^^^^^^^^^^^^^^^^
  File "/home/ubuntu/airflow_venv/lib/python3.12/site-packages/fsspec/asyn.py", line 118, in wrapper
    return sync(self.loop, func, *args, **kwargs)
           ^^^^^^^^^^^^^^^^^^^^^^^^^^^^^^^^^^^^^^
  File "/home/ubuntu/airflow_venv/lib/python3.12/site-packages/fsspec/asyn.py", line 103, in sync
    raise return_result
  File "/home/ubuntu/airflow_venv/lib/python3.12/site-packages/fsspec/asyn.py", line 56, in _runner
    result[0] = await coro
                ^^^^^^^^^^
  File "/home/ubuntu/airflow_venv/lib/python3.12/site-packages/s3fs/core.py", line 365, in _call_s3
    return await _error_wrapper(
           ^^^^^^^^^^^^^^^^^^^^^
  File "/home/ubuntu/airflow_venv/lib/python3.12/site-packages/s3fs/core.py", line 145, in _error_wrapper
    raise err
PermissionError: The AWS Access Key Id you provided does not exist in our records.
[2024-09-04T05:09:02.518+0000] {logging_mixin.py:190} INFO - Task instance in failure state
[2024-09-04T05:09:02.519+0000] {logging_mixin.py:190} INFO - Task start:2024-09-04 05:09:00.490695+00:00 end:2024-09-04 05:09:02.518416+00:00 duration:2.027721
[2024-09-04T05:09:02.519+0000] {logging_mixin.py:190} INFO - Task:<Task(PythonOperator): transform_load_weather_data> dag:<DAG: weather_dag> dagrun:<DagRun weather_dag @ 2024-09-04 05:06:47.581164+00:00: manual__2024-09-04T05:06:47.581164+00:00, state:running, queued_at: 2024-09-04 05:06:47.587371+00:00. externally triggered: True>
[2024-09-04T05:09:02.519+0000] {logging_mixin.py:190} INFO - Failure caused by The AWS Access Key Id you provided does not exist in our records.
[2024-09-04T05:09:02.519+0000] {taskinstance.py:1225} INFO - Marking task as UP_FOR_RETRY. dag_id=weather_dag, task_id=transform_load_weather_data, run_id=manual__2024-09-04T05:06:47.581164+00:00, execution_date=20240904T050647, start_date=20240904T050900, end_date=20240904T050902
[2024-09-04T05:09:02.534+0000] {taskinstance.py:340} INFO - ::group::Post task execution logs
[2024-09-04T05:09:02.535+0000] {standard_task_runner.py:124} ERROR - Failed to execute job 12 for task transform_load_weather_data (The AWS Access Key Id you provided does not exist in our records.; 11305)
Traceback (most recent call last):
  File "/home/ubuntu/airflow_venv/lib/python3.12/site-packages/s3fs/core.py", line 113, in _error_wrapper
    return await func(*args, **kwargs)
           ^^^^^^^^^^^^^^^^^^^^^^^^^^^
  File "/home/ubuntu/airflow_venv/lib/python3.12/site-packages/aiobotocore/client.py", line 412, in _make_api_call
    raise error_class(parsed_response, operation_name)
botocore.exceptions.ClientError: An error occurred (InvalidAccessKeyId) when calling the PutObject operation: The AWS Access Key Id you provided does not exist in our records.

The above exception was the direct cause of the following exception:

Traceback (most recent call last):
  File "/home/ubuntu/airflow_venv/lib/python3.12/site-packages/airflow/task/task_runner/standard_task_runner.py", line 117, in _start_by_fork
    ret = args.func(args, dag=self.dag)
          ^^^^^^^^^^^^^^^^^^^^^^^^^^^^^
  File "/home/ubuntu/airflow_venv/lib/python3.12/site-packages/airflow/cli/cli_config.py", line 49, in command
    return func(*args, **kwargs)
           ^^^^^^^^^^^^^^^^^^^^^
  File "/home/ubuntu/airflow_venv/lib/python3.12/site-packages/airflow/utils/cli.py", line 115, in wrapper
    return f(*args, **kwargs)
           ^^^^^^^^^^^^^^^^^^
  File "/home/ubuntu/airflow_venv/lib/python3.12/site-packages/airflow/cli/commands/task_command.py", line 483, in task_run
    task_return_code = _run_task_by_selected_method(args, _dag, ti)
                       ^^^^^^^^^^^^^^^^^^^^^^^^^^^^^^^^^^^^^^^^^^^^
  File "/home/ubuntu/airflow_venv/lib/python3.12/site-packages/airflow/cli/commands/task_command.py", line 256, in _run_task_by_selected_method
    return _run_raw_task(args, ti)
           ^^^^^^^^^^^^^^^^^^^^^^^
  File "/home/ubuntu/airflow_venv/lib/python3.12/site-packages/airflow/cli/commands/task_command.py", line 341, in _run_raw_task
    return ti._run_raw_task(
           ^^^^^^^^^^^^^^^^^
  File "/home/ubuntu/airflow_venv/lib/python3.12/site-packages/airflow/utils/session.py", line 97, in wrapper
    return func(*args, session=session, **kwargs)
           ^^^^^^^^^^^^^^^^^^^^^^^^^^^^^^^^^^^^^^
  File "/home/ubuntu/airflow_venv/lib/python3.12/site-packages/airflow/models/taskinstance.py", line 2995, in _run_raw_task
    return _run_raw_task(
           ^^^^^^^^^^^^^^
  File "/home/ubuntu/airflow_venv/lib/python3.12/site-packages/airflow/models/taskinstance.py", line 273, in _run_raw_task
    TaskInstance._execute_task_with_callbacks(
  File "/home/ubuntu/airflow_venv/lib/python3.12/site-packages/airflow/models/taskinstance.py", line 3149, in _execute_task_with_callbacks
    result = self._execute_task(context, task_orig)
             ^^^^^^^^^^^^^^^^^^^^^^^^^^^^^^^^^^^^^^
  File "/home/ubuntu/airflow_venv/lib/python3.12/site-packages/airflow/models/taskinstance.py", line 3173, in _execute_task
    return _execute_task(self, context, task_orig)
           ^^^^^^^^^^^^^^^^^^^^^^^^^^^^^^^^^^^^^^^
  File "/home/ubuntu/airflow_venv/lib/python3.12/site-packages/airflow/models/taskinstance.py", line 767, in _execute_task
    result = _execute_callable(context=context, **execute_callable_kwargs)
             ^^^^^^^^^^^^^^^^^^^^^^^^^^^^^^^^^^^^^^^^^^^^^^^^^^^^^^^^^^^^^
  File "/home/ubuntu/airflow_venv/lib/python3.12/site-packages/airflow/models/taskinstance.py", line 733, in _execute_callable
    return ExecutionCallableRunner(
           ^^^^^^^^^^^^^^^^^^^^^^^^
  File "/home/ubuntu/airflow_venv/lib/python3.12/site-packages/airflow/utils/operator_helpers.py", line 252, in run
    return self.func(*args, **kwargs)
           ^^^^^^^^^^^^^^^^^^^^^^^^^^
  File "/home/ubuntu/airflow_venv/lib/python3.12/site-packages/airflow/models/baseoperator.py", line 406, in wrapper
    return func(self, *args, **kwargs)
           ^^^^^^^^^^^^^^^^^^^^^^^^^^^
  File "/home/ubuntu/airflow_venv/lib/python3.12/site-packages/airflow/operators/python.py", line 238, in execute
    return_value = self.execute_callable()
                   ^^^^^^^^^^^^^^^^^^^^^^^
  File "/home/ubuntu/airflow_venv/lib/python3.12/site-packages/airflow/operators/python.py", line 256, in execute_callable
    return runner.run(*self.op_args, **self.op_kwargs)
           ^^^^^^^^^^^^^^^^^^^^^^^^^^^^^^^^^^^^^^^^^^^
  File "/home/ubuntu/airflow_venv/lib/python3.12/site-packages/airflow/utils/operator_helpers.py", line 252, in run
    return self.func(*args, **kwargs)
           ^^^^^^^^^^^^^^^^^^^^^^^^^^
  File "/home/ubuntu/airflow/dags/weather_dag.py", line 50, in transform_load_data
    df_data.to_csv(f"s3://weatherapiairflowyoutubebucket-yml/{dt_string}.csv", index=False, storage_options=aws_credentials)
  File "/home/ubuntu/airflow_venv/lib/python3.12/site-packages/pandas/util/_decorators.py", line 333, in wrapper
    return func(*args, **kwargs)
           ^^^^^^^^^^^^^^^^^^^^^
  File "/home/ubuntu/airflow_venv/lib/python3.12/site-packages/pandas/core/generic.py", line 3967, in to_csv
    return DataFrameRenderer(formatter).to_csv(
           ^^^^^^^^^^^^^^^^^^^^^^^^^^^^^^^^^^^^
  File "/home/ubuntu/airflow_venv/lib/python3.12/site-packages/pandas/io/formats/format.py", line 1014, in to_csv
    csv_formatter.save()
  File "/home/ubuntu/airflow_venv/lib/python3.12/site-packages/pandas/io/formats/csvs.py", line 251, in save
    with get_handle(
  File "/home/ubuntu/airflow_venv/lib/python3.12/site-packages/pandas/io/common.py", line 157, in __exit__
    self.close()
  File "/home/ubuntu/airflow_venv/lib/python3.12/site-packages/pandas/io/common.py", line 144, in close
    handle.close()
  File "/home/ubuntu/airflow_venv/lib/python3.12/site-packages/fsspec/spec.py", line 2035, in close
    self.flush(force=True)
  File "/home/ubuntu/airflow_venv/lib/python3.12/site-packages/fsspec/spec.py", line 1899, in flush
    if self._upload_chunk(final=force) is not False:
       ^^^^^^^^^^^^^^^^^^^^^^^^^^^^^^^
  File "/home/ubuntu/airflow_venv/lib/python3.12/site-packages/s3fs/core.py", line 2371, in _upload_chunk
    self.commit()
  File "/home/ubuntu/airflow_venv/lib/python3.12/site-packages/s3fs/core.py", line 2389, in commit
    write_result = self._call_s3("put_object", **kw)
                   ^^^^^^^^^^^^^^^^^^^^^^^^^^^^^^^^^
  File "/home/ubuntu/airflow_venv/lib/python3.12/site-packages/s3fs/core.py", line 2234, in _call_s3
    return self.fs.call_s3(method, self.s3_additional_kwargs, *kwarglist, **kwargs)
           ^^^^^^^^^^^^^^^^^^^^^^^^^^^^^^^^^^^^^^^^^^^^^^^^^^^^^^^^^^^^^^^^^^^^^^^^
  File "/home/ubuntu/airflow_venv/lib/python3.12/site-packages/fsspec/asyn.py", line 118, in wrapper
    return sync(self.loop, func, *args, **kwargs)
           ^^^^^^^^^^^^^^^^^^^^^^^^^^^^^^^^^^^^^^
  File "/home/ubuntu/airflow_venv/lib/python3.12/site-packages/fsspec/asyn.py", line 103, in sync
    raise return_result
  File "/home/ubuntu/airflow_venv/lib/python3.12/site-packages/fsspec/asyn.py", line 56, in _runner
    result[0] = await coro
                ^^^^^^^^^^
  File "/home/ubuntu/airflow_venv/lib/python3.12/site-packages/s3fs/core.py", line 365, in _call_s3
    return await _error_wrapper(
           ^^^^^^^^^^^^^^^^^^^^^
  File "/home/ubuntu/airflow_venv/lib/python3.12/site-packages/s3fs/core.py", line 145, in _error_wrapper
    raise err
PermissionError: The AWS Access Key Id you provided does not exist in our records.
[2024-09-04T05:09:02.581+0000] {local_task_job_runner.py:261} INFO - Task exited with return code 1
[2024-09-04T05:09:02.590+0000] {taskinstance.py:3891} INFO - 0 downstream tasks scheduled from follow-on schedule check
[2024-09-04T05:09:02.591+0000] {local_task_job_runner.py:240} INFO - ::endgroup::
